<?xml version="1.0"?>
<robot name="simple_rover">

<material name='blue'>
	<color rgba='0 0 0.8 1'/>
</material>

<material name='white'>
	<color rgba='1 1 1 1'/>
</material>

  <link name="base_link">
    <visual>
      <geometry>
        <box size="0.6 0.4 0.2"/>
      </geometry>
      <origin xyz="0 0 0.1" rpy="0 0 0" />
      <material name='blue'/>
    </visual>

    <collision>
      <geometry>
        <box size="0.6 0.4 0.2"/>
      </geometry>
    </collision>

    <inertial>
      <mass value="0.5"/>
      <origin rpy="0 0 0" xyz="0 0 0"/>
      <inertia ixx="0.0008333333333333335" ixy="0" ixz="0" iyy="0.0008333333333333335" iyz="0" izz="0.0008333333333333335"/>
    </inertial>
  </link>

  <link name="back_right_wheel">
    <visual>
      <geometry>
        <cylinder length='0.04' radius='0.1'/>
      </geometry>
      <origin xyz="0 0 0" rpy="1.57 0 0" />
      <material name='white'/>
    </visual>

    <collision>
      <geometry>
        <cylinder length='0.04' radius='0.1'/>
      </geometry>
    </collision>

    <inertial>
      <mass value="0.5"/>
      <origin rpy="0 0 0" xyz="0 0 0"/>
      <inertia ixx="0.0008333333333333335" ixy="0" ixz="0" iyy="0.0008333333333333335" iyz="0" izz="0.0008333333333333335"/>
    </inertial>
  </link>

  <link name="back_left_wheel">
    <visual>
      <geometry>
        <cylinder length='0.04' radius='0.1'/>
      </geometry>
      <origin xyz="0 0 0" rpy="1.57 0 0" />
      <material name='white'/>
    </visual>

    <collision>
      <geometry>
        <cylinder length='0.04' radius='0.1'/>
      </geometry>
    </collision>

    <inertial>
      <mass value="0.5"/>
      <origin rpy="0 0 0" xyz="0 0 0"/>
      <inertia ixx="0.0008333333333333335" ixy="0" ixz="0" iyy="0.0008333333333333335" iyz="0" izz="0.0008333333333333335"/>
    </inertial>
  </link>

  <link name="front_left_wheel">
    <visual>
      <geometry>
        <cylinder length='0.04' radius='0.1'/>
      </geometry>
      <origin xyz="0 0 0" rpy="1.57 0 0" />
      <material name='white'/>
    </visual>

    <collision>
      <geometry>
        <cylinder length='0.04' radius='0.1'/>
      </geometry>
    </collision>

    <inertial>
      <mass value="0.5"/>
      <origin rpy="0 0 0" xyz="0 0 0"/>
      <inertia ixx="0.0008333333333333335" ixy="0" ixz="0" iyy="0.0008333333333333335" iyz="0" izz="0.0008333333333333335"/>
    </inertial>
  </link>

  <link name="front_right_wheel">
    <visual>
      <geometry>
        <cylinder length='0.04' radius='0.1'/>
      </geometry>
      <origin xyz="0 0 0" rpy="1.57 0 0" />
      <material name='white'/>
    </visual>

    <collision>
      <geometry>
        <cylinder length='0.04' radius='0.1'/>
      </geometry>
    </collision>

    <inertial>
      <mass value="0.5"/>
      <origin rpy="0 0 0" xyz="0 0 0"/>
      <inertia ixx="0.0008333333333333335" ixy="0" ixz="0" iyy="0.0008333333333333335" iyz="0" izz="0.0008333333333333335"/>
    </inertial>
  </link>

  <joint name="back_right_wheel_joint" type="continuous">
    <parent link = "base_link"/>
    <child link = "back_right_wheel"/>
    <origin xyz="-0.15 -0.225 0"/>
    <axis xyz="0 1 0"/>
        <limit effort="10000" velocity="1000"/>
    <joint_properties damping="1.0" friction="1.0"/>
  </joint>

  <joint name="back_left_wheel_joint" type="continuous">
    <parent link = "base_link"/>
    <child link = "back_left_wheel"/>
    <origin xyz="-0.15 0.225 0"/>
    <axis xyz="0 1 0"/>
        <limit effort="10000" velocity="1000"/>
    <joint_properties damping="1.0" friction="1.0"/>
  </joint>

  <joint name="front_left_wheel_joint" type="continuous">
    <parent link = "base_link"/>
    <child link = "front_left_wheel"/>
    <origin xyz="0.15 0.225 0"/>
    <axis xyz="0 1 0"/>
        <limit effort="10000" velocity="1000"/>
    <joint_properties damping="1.0" friction="1.0"/>
  </joint>

  <joint name="front_right_wheel_joint" type="continuous">
    <parent link = "base_link"/>
    <child link = "front_right_wheel"/>
    <origin xyz="0.15 -0.225 0"/>
    <axis xyz="0 1 0"/>
        <limit effort="10000" velocity="1000"/>
    <joint_properties damping="1.0" friction="1.0"/>
  </joint>

    <gazebo reference="front_right_wheel">
    <kp>1000000000000000000000000000.0</kp>
    <kd>1000000000000000000000000000.0</kd>
    <mu1>10.0</mu1>
    <mu2>10.0</mu2>
    <material>Gazebo/Orange</material>
  </gazebo>

  <gazebo reference="front_left_wheel">
    <kp>1000000000000000000000000000.0</kp>
    <kd>1000000000000000000000000000.0</kd>
    <mu1>10.0</mu1>
    <mu2>10.0</mu2>
    <material>Gazebo/Orange</material>
  </gazebo>

  <gazebo reference="back_left_wheel">
    <kp>1000000000000000000000000000.0</kp>
    <kd>1000000000000000000000000000.0</kd>
    <mu1>10.0</mu1>
    <mu2>10.0</mu2>
    <material>Gazebo/Orange</material>
  </gazebo>
  <gazebo reference="back_right_wheel">
    <kp>1000000000000000000000000000.0</kp>
    <kd>1000000000000000000000000000.0</kd>
    <mu1>10.0</mu1>
    <mu2>10.0</mu2>
    <material>Gazebo/Orange</material>
  </gazebo>

<!-- PLUGINS -->


  <!-- JOINT PUBLISHER -->
  <gazebo>
    <plugin name="box_bot_joint_state" filename="libgazebo_ros_joint_state_publisher.so">
      <ros>
          <remapping>~/out:=joint_states</remapping>
      </ros>
      <update_rate>30</update_rate>

      <joint_name>front_left_wheel_joint</joint_name>
      <joint_name>front_right_wheel_joint</joint_name>
      <!-- <joint_name>back_left_wheel_joint</joint_name>
      <joint_name>back_right_wheel_joint</joint_name> -->
      
    </plugin>
  </gazebo>

  <!-- Differential drive -->
  <gazebo>
    <plugin filename="libgazebo_ros_diff_drive.so" name="differential_drive_controller">

      <!-- wheels -->
      <!-- <left_joint>front_left_wheel_joint</left_joint>
      <right_joint>front_right_wheel_joint</right_joint> -->
      <left_joint>front_left_wheel_joint</left_joint>
      <right_joint>front_right_wheel_joint</right_joint>

      <!-- kinematics -->
      <wheel_separation>0.1</wheel_separation>
      <wheel_diameter>0.07</wheel_diameter>

      <!-- limits -->
      <max_wheel_torque>1.0</max_wheel_torque>
      <max_wheel_acceleration>2.0</max_wheel_acceleration>

      <!-- output -->
      <publish_odom>true</publish_odom>
      <publish_odom_tf>true</publish_odom_tf>

      <odometry_frame>odom</odometry_frame>
      <robot_base_frame>base_link</robot_base_frame>

    </plugin>
  </gazebo>

</robot>