<?xml version="1.0"?>
<robot name="simple_rover">

<material name='blue'>
	<color rgba='0 0 0.8 1'/>
</material>

<material name='white'>
	<color rgba='1 1 1 1'/>
</material>

  <link name="base_link">
    <visual>
      <geometry>
        <box size="0.6 0.4 0.2"/>
      </geometry>
      <origin xyz="0 0 0.1" rpy="0 0 0" />
      <material name='blue'/>
    </visual>

    <collision>
      <geometry>
        <box size="0.6 0.4 0.2"/>
      </geometry>
    </collision>

    <inertial>
      <mass value="0.5"/>
      <origin rpy="0 0 0" xyz="0 0 0"/>
      <inertia ixx="0.0008333333333333335" ixy="0" ixz="0" iyy="0.0008333333333333335" iyz="0" izz="0.0008333333333333335"/>
    </inertial>
  </link>

  <link name="back_right_wheel">
    <visual>
      <geometry>
        <cylinder length='0.04' radius='0.1'/>
      </geometry>
      <origin xyz="0 0 0" rpy="1.57 0 0" />
      <material name='white'/>
    </visual>

    <collision>
      <geometry>
        <cylinder length='0.04' radius='0.1'/>
      </geometry>
    </collision>

    <inertial>
      <mass value="0.5"/>
      <origin rpy="0 0 0" xyz="0 0 0"/>
      <inertia ixx="0.0008333333333333335" ixy="0" ixz="0" iyy="0.0008333333333333335" iyz="0" izz="0.0008333333333333335"/>
    </inertial>
  </link>

  <link name="back_left_wheel">
    <visual>
      <geometry>
        <cylinder length='0.04' radius='0.1'/>
      </geometry>
      <origin xyz="0 0 0" rpy="1.57 0 0" />
      <material name='white'/>
    </visual>

    <collision>
      <geometry>
        <cylinder length='0.04' radius='0.1'/>
      </geometry>
    </collision>

    <inertial>
      <mass value="0.5"/>
      <origin rpy="0 0 0" xyz="0 0 0"/>
      <inertia ixx="0.0008333333333333335" ixy="0" ixz="0" iyy="0.0008333333333333335" iyz="0" izz="0.0008333333333333335"/>
    </inertial>
  </link>

  <link name="front_left_wheel">
    <visual>
      <geometry>
        <cylinder length='0.04' radius='0.1'/>
      </geometry>
      <origin xyz="0 0 0" rpy="1.57 0 0" />
      <material name='white'/>
    </visual>

    <collision>
      <geometry>
        <cylinder length='0.04' radius='0.1'/>
      </geometry>
    </collision>

    <inertial>
      <mass value="0.5"/>
      <origin rpy="0 0 0" xyz="0 0 0"/>
      <inertia ixx="0.0008333333333333335" ixy="0" ixz="0" iyy="0.0008333333333333335" iyz="0" izz="0.0008333333333333335"/>
    </inertial>
  </link>

  <link name="front_right_wheel">
    <visual>
      <geometry>
        <cylinder length='0.04' radius='0.1'/>
      </geometry>
      <origin xyz="0 0 0" rpy="1.57 0 0" />
      <material name='white'/>
    </visual>

    <collision>
      <geometry>
        <cylinder length='0.04' radius='0.1'/>
      </geometry>
    </collision>

    <inertial>
      <mass value="0.5"/>
      <origin rpy="0 0 0" xyz="0 0 0"/>
      <inertia ixx="0.0008333333333333335" ixy="0" ixz="0" iyy="0.0008333333333333335" iyz="0" izz="0.0008333333333333335"/>
    </inertial>
  </link>

  <joint name="back_right_wheel_joint" type="continuous">
    <parent link = "base_link"/>
    <child link = "back_right_wheel"/>
    <origin xyz="-0.15 -0.225 0"/>
    <axis xyz="0 1 0"/>
    <dynamics damping="0.1" friction="0.05"/>
  </joint>

  <joint name="back_left_wheel_joint" type="continuous">
    <parent link = "base_link"/>
    <child link = "back_left_wheel"/>
    <origin xyz="-0.15 0.225 0"/>
    <axis xyz="0 1 0"/>
    <dynamics damping="0.1" friction="0.05"/>
  </joint>

  <joint name="front_left_wheel_joint" type="continuous">
    <parent link = "base_link"/>
    <child link = "front_left_wheel"/>
    <origin xyz="0.15 0.225 0"/>
    <axis xyz="0 1 0"/>
    <dynamics damping="0.1" friction="0.05"/>
  </joint>

  <joint name="front_right_wheel_joint" type="continuous">
    <parent link = "base_link"/>
    <child link = "front_right_wheel"/>
    <origin xyz="0.15 -0.225 0"/>
    <axis xyz="0 1 0"/>
    <dynamics damping="0.1" friction="0.05"/>
  </joint>

</robot>
